Workbook

Sheet AQ
A1: Nama | B1: Nomor Pendaftaran | C1: Jenjang | D1: Nilai Tajwid | E1: Nilai Kelancaran | F1: Rekomendasi | G1: Nama Penguji | H1: Catatan | I1: Nilai Rerata
A2: =IFERROR(__xludf.DUMMYFUNCTION("importrange(""https://docs.google.com/spreadsheets/d/1UbhKnOqCU4kQCzSZuNAARq9KSZBV7aq-k2gR_yYLDOg/edit?resourcekey=&gid=976856029#gid=976856029"",""Form Responses 1!C2:J1000"")"),"Aviccena Syahdan Haqoni ") -> Aviccena Syahdan Haqoni | B2: =IFERROR(__xludf.DUMMYFUNCTION("""COMPUTED_VALUE"""),"A250060") -> A250060 | C2: =IFERROR(__xludf.DUMMYFUNCTION("""COMPUTED_VALUE"""),"MTs Putra") -> MTs Putra | D2: =IFERROR(__xludf.DUMMYFUNCTION("""COMPUTED_VALUE"""),70.0) -> 70 | E2: =IFERROR(__xludf.DUMMYFUNCTION("""COMPUTED_VALUE"""),50.0) -> 50 | F2: =IFERROR(__xludf.DUMMYFUNCTION("""COMPUTED_VALUE"""),"C. Ditolak") -> C. Ditolak | G2: =IFERROR(__xludf.DUMMYFUNCTION("""COMPUTED_VALUE"""),"Fuad Khomsatun") -> Fuad Khomsatun | H2: =IFERROR(__xludf.DUMMYFUNCTION("""COMPUTED_VALUE"""),"Makhroj cukup bagus, tapi hukum Tajwid yang sangat kurang") -> Makhroj cukup bagus, tapi hukum Tajwid yang sangat kurang | I2: =average(D2:E2) -> 60
A3: =IFERROR(__xludf.DUMMYFUNCTION("""COMPUTED_VALUE"""),"Syabban Ghazi Alfathan ") -> Syabban Ghazi Alfathan | B3: =IFERROR(__xludf.DUMMYFUNCTION("""COMPUTED_VALUE"""),"B250025") -> B250025 | C3: =IFERROR(__xludf.DUMMYFUNCTION("""COMPUTED_VALUE"""),"IL Putra") -> IL Putra | D3: =IFERROR(__xludf.DUMMYFUNCTION("""COMPUTED_VALUE"""),85.0) -> 85 | E3: =IFERROR(__xludf.DUMMYFUNCTION("""COMPUTED_VALUE"""),50.0) -> 50 | F3: =IFERROR(__xludf.DUMMYFUNCTION("""COMPUTED_VALUE"""),"B. Cadangan") -> B. Cadangan | G3: =IFERROR(__xludf.DUMMYFUNCTION("""COMPUTED_VALUE"""),"Fuad Khomsatun") -> Fuad Khomsatun | H3: =IFERROR(__xludf.DUMMYFUNCTION("""COMPUTED_VALUE"""),"1. Dari 3 soal yg diberikan, ananda hanya menjawab 1 saja itupun tidak begitu lancar 2. Waqof dan ibtida, tidak tepat 3. Makhroj cukup bagus ") -> 1. Dari 3 soal yg diberikan, ananda hanya menjawab 1 saja itupun tidak begitu lancar 2. Waqof dan ibtida, tidak tepat 3. Makhroj cukup bagus | I3: =average(D3:E3) -> 67.5
A4: =IFERROR(__xludf.DUMMYFUNCTION("""COMPUTED_VALUE"""),"Daffa Taamir Alfarizi ") -> Daffa Taamir Alfarizi | B4: =IFERROR(__xludf.DUMMYFUNCTION("""COMPUTED_VALUE"""),"A250008") -> A250008 | C4: =IFERROR(__xludf.DUMMYFUNCTION("""COMPUTED_VALUE"""),"MTs Putra") -> MTs Putra | D4: =IFERROR(__xludf.DUMMYFUNCTION("""COMPUTED_VALUE"""),93.0) -> 93 | E4: =IFERROR(__xludf.DUMMYFUNCTION("""COMPUTED_VALUE"""),90.0) -> 90 | F4: =IFERROR(__xludf.DUMMYFUNCTION("""COMPUTED_VALUE"""),"A. Diterima") -> A. Diterima | G4: =IFERROR(__xludf.DUMMYFUNCTION("""COMPUTED_VALUE"""),"Fuad Khomsatun") -> Fuad Khomsatun | H4: =IFERROR(__xludf.DUMMYFUNCTION("""COMPUTED_VALUE"""),"semuanya Alhamdulillah kongkrit, tidak ada keraguan didalamnya. Namun pada waqof ibtida perlu diperbaiki") -> semuanya Alhamdulillah kongkrit, tidak ada keraguan didalamnya. Namun pada waqof ibtida perlu diperbaiki | I4: =average(D4:E4) -> 91.5
A5: =IFERROR(__xludf.DUMMYFUNCTION("""COMPUTED_VALUE"""),"Aisyah") -> Aisyah | B5: =IFERROR(__xludf.DUMMYFUNCTION("""COMPUTED_VALUE"""),"D250005") -> D250005 | C5: =IFERROR(__xludf.DUMMYFUNCTION("""COMPUTED_VALUE"""),"MTs Putri") -> MTs Putri | D5: =IFERROR(__xludf.DUMMYFUNCTION("""COMPUTED_VALUE"""),80.0) -> 80 | E5: =IFERROR(__xludf.DUMMYFUNCTION("""COMPUTED_VALUE"""),80.0) -> 80 | F5: =IFERROR(__xludf.DUMMYFUNCTION("""COMPUTED_VALUE"""),"A. Diterima") -> A. Diterima | G5: =IFERROR(__xludf.DUMMYFUNCTION("""COMPUTED_VALUE"""),"Andi Fatimah Azzahra Rahman") -> Andi Fatimah Azzahra Rahman | H5: =IFERROR(__xludf.DUMMYFUNCTION("""COMPUTED_VALUE"""),"Di terima dan perlu bimbingan lagi sebelum masuk smp") -> Di terima dan perlu bimbingan lagi sebelum masuk smp | I5: =average(D5:E5) -> 80
A6: =IFERROR(__xludf.DUMMYFUNCTION("""COMPUTED_VALUE"""),"Aina Syahmina Givani ") -> Aina Syahmina Givani | B6: =IFERROR(__xludf.DUMMYFUNCTION("""COMPUTED_VALUE"""),"D250006") -> D250006 | C6: =IFERROR(__xludf.DUMMYFUNCTION("""COMPUTED_VALUE"""),"MTs Putri") -> MTs Putri | D6: =IFERROR(__xludf.DUMMYFUNCTION("""COMPUTED_VALUE"""),81.0) -> 81 | E6: =IFERROR(__xludf.DUMMYFUNCTION("""COMPUTED_VALUE"""),80.0) -> 80 | F6: =IFERROR(__xludf.DUMMYFUNCTION("""COMPUTED_VALUE"""),"A. Diterima") -> A. Diterima | G6: =IFERROR(__xludf.DUMMYFUNCTION("""COMPUTED_VALUE"""),"Andi Fatimah Azzahra Rahman") -> Andi Fatimah Azzahra Rahman | H6: =IFERROR(__xludf.DUMMYFUNCTION("""COMPUTED_VALUE"""),"Di terima dan perlu bimbingan lagi sebelum masuk smp") -> Di terima dan perlu bimbingan lagi sebelum masuk smp | I6: =average(D6:E6) -> 80.5
A7: =IFERROR(__xludf.DUMMYFUNCTION("""COMPUTED_VALUE"""),"Keyza Qaireen") -> Keyza Qaireen | B7: =IFERROR(__xludf.DUMMYFUNCTION("""COMPUTED_VALUE"""),"D250009") -> D250009 | C7: =IFERROR(__xludf.DUMMYFUNCTION("""COMPUTED_VALUE"""),"MTs Putri") -> MTs Putri | D7: =IFERROR(__xludf.DUMMYFUNCTION("""COMPUTED_VALUE"""),85.0) -> 85 | E7: =IFERROR(__xludf.DUMMYFUNCTION("""COMPUTED_VALUE"""),85.0) -> 85 | F7: =IFERROR(__xludf.DUMMYFUNCTION("""COMPUTED_VALUE"""),"A. Diterima") -> A. Diterima | G7: =IFERROR(__xludf.DUMMYFUNCTION("""COMPUTED_VALUE"""),"Andi Fatimah Azzahra Rahman") -> Andi Fatimah Azzahra Rahman | I7: =average(D7:E7) -> 85
A8: =IFERROR(__xludf.DUMMYFUNCTION("""COMPUTED_VALUE"""),"Sarah Afifa ") -> Sarah Afifa | B8: =IFERROR(__xludf.DUMMYFUNCTION("""COMPUTED_VALUE"""),"D250015") -> D250015 | C8: =IFERROR(__xludf.DUMMYFUNCTION("""COMPUTED_VALUE"""),"MTs Putri") -> MTs Putri | D8: =IFERROR(__xludf.DUMMYFUNCTION("""COMPUTED_VALUE"""),90.0) -> 90 | E8: =IFERROR(__xludf.DUMMYFUNCTION("""COMPUTED_VALUE"""),80.0) -> 80 | F8: =IFERROR(__xludf.DUMMYFUNCTION("""COMPUTED_VALUE"""),"A. Diterima") -> A. Diterima | G8: =IFERROR(__xludf.DUMMYFUNCTION("""COMPUTED_VALUE"""),"Andi Fatimah Azzahra Rahman") -> Andi Fatimah Azzahra Rahman | H8: =IFERROR(__xludf.DUMMYFUNCTION("""COMPUTED_VALUE"""),"Perbanyak tilawah al quran sebelum masuk pondok agar lebih lancar lagi") -> Perbanyak tilawah al quran sebelum masuk pondok agar lebih lancar lagi | I8: =average(D8:E8) -> 85
A9: =IFERROR(__xludf.DUMMYFUNCTION("""COMPUTED_VALUE"""),"Adibah Saefulloh") -> Adibah Saefulloh | B9: =IFERROR(__xludf.DUMMYFUNCTION("""COMPUTED_VALUE"""),"D250003") -> D250003 | C9: =IFERROR(__xludf.DUMMYFUNCTION("""COMPUTED_VALUE"""),"MTs Putri") -> MTs Putri | D9: =IFERROR(__xludf.DUMMYFUNCTION("""COMPUTED_VALUE"""),70.0) -> 70 | E9: =IFERROR(__xludf.DUMMYFUNCTION("""COMPUTED_VALUE"""),70.0) -> 70 | F9: =IFERROR(__xludf.DUMMYFUNCTION("""COMPUTED_VALUE"""),"A. Diterima") -> A. Diterima | G9: =IFERROR(__xludf.DUMMYFUNCTION("""COMPUTED_VALUE"""),"Andi Fatimah Azzahra Rahman") -> Andi Fatimah Azzahra Rahman | H9: =IFERROR(__xludf.DUMMYFUNCTION("""COMPUTED_VALUE"""),"Di terima dan perlu bimbingan lagi sebelum masuk smp") -> Di terima dan perlu bimbingan lagi sebelum masuk smp | I9: =average(D9:E9) -> 70
A10: =IFERROR(__xludf.DUMMYFUNCTION("""COMPUTED_VALUE"""),"Azka Ulinnuha") -> Azka Ulinnuha | B10: =IFERROR(__xludf.DUMMYFUNCTION("""COMPUTED_VALUE"""),"B250009") -> B250009 | C10: =IFERROR(__xludf.DUMMYFUNCTION("""COMPUTED_VALUE"""),"IL Putra") -> IL Putra | D10: =IFERROR(__xludf.DUMMYFUNCTION("""COMPUTED_VALUE"""),70.0) -> 70 | E10: =IFERROR(__xludf.DUMMYFUNCTION("""COMPUTED_VALUE"""),70.0) -> 70 | F10: =IFERROR(__xludf.DUMMYFUNCTION("""COMPUTED_VALUE"""),"B. Cadangan") -> B. Cadangan | G10: =IFERROR(__xludf.DUMMYFUNCTION("""COMPUTED_VALUE"""),"Jusman") -> Jusman | I10: =average(D10:E10) -> 70
A11: =IFERROR(__xludf.DUMMYFUNCTION("""COMPUTED_VALUE"""),"Muhammad Hamudi Alfarizi") -> Muhammad Hamudi Alfarizi | B11: =IFERROR(__xludf.DUMMYFUNCTION("""COMPUTED_VALUE"""),"A250062") -> A250062 | C11: =IFERROR(__xludf.DUMMYFUNCTION("""COMPUTED_VALUE"""),"MTs Putra") -> MTs Putra | D11: =IFERROR(__xludf.DUMMYFUNCTION("""COMPUTED_VALUE"""),80.0) -> 80 | E11: =IFERROR(__xludf.DUMMYFUNCTION("""COMPUTED_VALUE"""),85.0) -> 85 | F11: =IFERROR(__xludf.DUMMYFUNCTION("""COMPUTED_VALUE"""),"B. Cadangan") -> B. Cadangan | G11: =IFERROR(__xludf.DUMMYFUNCTION("""COMPUTED_VALUE"""),"Agus Cahyono") -> Agus Cahyono | H11: =IFERROR(__xludf.DUMMYFUNCTION("""COMPUTED_VALUE"""),"1. Ananda bacaanya lancar , tp masih perlu perbaikan di tahsinnya. 2. Masih ada beberapa hukum bacaan yg kurang tepat, seperti mad tobi'i yg tidak tertunaikan. 3. Terkadang terburu-buru sehingga ada huruf yg terbalik penyebutannya.") -> 1. Ananda bacaanya lancar , tp masih perlu perbaikan di tahsinnya. 2. Masih ada beberapa hukum bacaan yg kurang tepat, seperti mad tobi'i yg tidak tertunaikan. 3. Terkadang terburu-buru sehingga ada huruf yg terbalik penyebutannya. | I11: =average(D11:E11) -> 82.5
A12: =IFERROR(__xludf.DUMMYFUNCTION("""COMPUTED_VALUE"""),"Ahmad Vickhy Wijaya") -> Ahmad Vickhy Wijaya | B12: =IFERROR(__xludf.DUMMYFUNCTION("""COMPUTED_VALUE"""),"A250073") -> A250073 | C12: =IFERROR(__xludf.DUMMYFUNCTION("""COMPUTED_VALUE"""),"MTs Putra") -> MTs Putra | D12: =IFERROR(__xludf.DUMMYFUNCTION("""COMPUTED_VALUE"""),70.0) -> 70 | E12: =IFERROR(__xludf.DUMMYFUNCTION("""COMPUTED_VALUE"""),75.0) -> 75 | F12: =IFERROR(__xludf.DUMMYFUNCTION("""COMPUTED_VALUE"""),"C. Ditolak") -> C. Ditolak | G12: =IFERROR(__xludf.DUMMYFUNCTION("""COMPUTED_VALUE"""),"Agus Cahyono") -> Agus Cahyono | I12: =average(D12:E12) -> 72.5
A13: =IFERROR(__xludf.DUMMYFUNCTION("""COMPUTED_VALUE"""),"Ambiya Addaruqutni J") -> Ambiya Addaruqutni J | B13: =IFERROR(__xludf.DUMMYFUNCTION("""COMPUTED_VALUE"""),"A250066") -> A250066 | C13: =IFERROR(__xludf.DUMMYFUNCTION("""COMPUTED_VALUE"""),"MTs Putra") -> MTs Putra | D13: =IFERROR(__xludf.DUMMYFUNCTION("""COMPUTED_VALUE"""),85.0) -> 85 | E13: =IFERROR(__xludf.DUMMYFUNCTION("""COMPUTED_VALUE"""),85.0) -> 85 | F13: =IFERROR(__xludf.DUMMYFUNCTION("""COMPUTED_VALUE"""),"B. Cadangan") -> B. Cadangan | G13: =IFERROR(__xludf.DUMMYFUNCTION("""COMPUTED_VALUE"""),"Agus Cahyono") -> Agus Cahyono | H13: =IFERROR(__xludf.DUMMYFUNCTION("""COMPUTED_VALUE"""),"1. Kelancarannya masih perlu di latih lagi 2. Hukum bacaan mad masih sering terlewat ") -> 1. Kelancarannya masih perlu di latih lagi 2. Hukum bacaan mad masih sering terlewat | I13: =average(D13:E13) -> 85
A14: =IFERROR(__xludf.DUMMYFUNCTION("""COMPUTED_VALUE"""),"Umar Fawwaz") -> Umar Fawwaz | B14: =IFERROR(__xludf.DUMMYFUNCTION("""COMPUTED_VALUE"""),"A250002") -> A250002 | C14: =IFERROR(__xludf.DUMMYFUNCTION("""COMPUTED_VALUE"""),"MTs Putra") -> MTs Putra | D14: =IFERROR(__xludf.DUMMYFUNCTION("""COMPUTED_VALUE"""),95.0) -> 95 | E14: =IFERROR(__xludf.DUMMYFUNCTION("""COMPUTED_VALUE"""),95.0) -> 95 | F14: =IFERROR(__xludf.DUMMYFUNCTION("""COMPUTED_VALUE"""),"A. Diterima") -> A. Diterima | G14: =IFERROR(__xludf.DUMMYFUNCTION("""COMPUTED_VALUE"""),"Agus Cahyono") -> Agus Cahyono | H14: =IFERROR(__xludf.DUMMYFUNCTION("""COMPUTED_VALUE"""),"Alhamdulillah") -> Alhamdulillah | I14: =average(D14:E14) -> 95
A15: =IFERROR(__xludf.DUMMYFUNCTION("""COMPUTED_VALUE"""),"Muhammad Asyam Abdullah") -> Muhammad Asyam Abdullah | B15: =IFERROR(__xludf.DUMMYFUNCTION("""COMPUTED_VALUE"""),"A250010") -> A250010 | C15: =IFERROR(__xludf.DUMMYFUNCTION("""COMPUTED_VALUE"""),"MTs Putra") -> MTs Putra | D15: =IFERROR(__xludf.DUMMYFUNCTION("""COMPUTED_VALUE"""),95.0) -> 95 | E15: =IFERROR(__xludf.DUMMYFUNCTION("""COMPUTED_VALUE"""),90.0) -> 90 | F15: =IFERROR(__xludf.DUMMYFUNCTION("""COMPUTED_VALUE"""),"A. Diterima") -> A. Diterima | G15: =IFERROR(__xludf.DUMMYFUNCTION("""COMPUTED_VALUE"""),"Agus Cahyono") -> Agus Cahyono | H15: =IFERROR(__xludf.DUMMYFUNCTION("""COMPUTED_VALUE"""),"Alhamdulillah") -> Alhamdulillah | I15: =average(D15:E15) -> 92.5
A16: =IFERROR(__xludf.DUMMYFUNCTION("""COMPUTED_VALUE"""),"Haneef Abdurahman") -> Haneef Abdurahman | B16: =IFERROR(__xludf.DUMMYFUNCTION("""COMPUTED_VALUE"""),"A250012") -> A250012 | C16: =IFERROR(__xludf.DUMMYFUNCTION("""COMPUTED_VALUE"""),"MTs Putra") -> MTs Putra | D16: =IFERROR(__xludf.DUMMYFUNCTION("""COMPUTED_VALUE"""),95.0) -> 95 | E16: =IFERROR(__xludf.DUMMYFUNCTION("""COMPUTED_VALUE"""),96.0) -> 96 | F16: =IFERROR(__xludf.DUMMYFUNCTION("""COMPUTED_VALUE"""),"A. Diterima") -> A. Diterima | G16: =IFERROR(__xludf.DUMMYFUNCTION("""COMPUTED_VALUE"""),"Jusman") -> Jusman | I16: =average(D16:E16) -> 95.5
A17: =IFERROR(__xludf.DUMMYFUNCTION("""COMPUTED_VALUE"""),"Donli") -> Donli | B17: =IFERROR(__xludf.DUMMYFUNCTION("""COMPUTED_VALUE"""),"B250001") -> B250001 | C17: =IFERROR(__xludf.DUMMYFUNCTION("""COMPUTED_VALUE"""),"IL Putra") -> IL Putra | D17: =IFERROR(__xludf.DUMMYFUNCTION("""COMPUTED_VALUE"""),75.0) -> 75 | E17: =IFERROR(__xludf.DUMMYFUNCTION("""COMPUTED_VALUE"""),70.0) -> 70 | F17: =IFERROR(__xludf.DUMMYFUNCTION("""COMPUTED_VALUE"""),"B. Cadangan") -> B. Cadangan | G17: =IFERROR(__xludf.DUMMYFUNCTION("""COMPUTED_VALUE"""),"Fuad Khomsatun") -> Fuad Khomsatun | H17: =IFERROR(__xludf.DUMMYFUNCTION("""COMPUTED_VALUE"""),"untuk makhroj lumayan bagus, tapi tajwid dan kelancaran masih kurang baik") -> untuk makhroj lumayan bagus, tapi tajwid dan kelancaran masih kurang baik | I17: =average(D17:E17) -> 72.5
A18: =IFERROR(__xludf.DUMMYFUNCTION("""COMPUTED_VALUE"""),"Adya Wiguna") -> Adya Wiguna | B18: =IFERROR(__xludf.DUMMYFUNCTION("""COMPUTED_VALUE"""),"A250013") -> A250013 | C18: =IFERROR(__xludf.DUMMYFUNCTION("""COMPUTED_VALUE"""),"MTs Putra") -> MTs Putra | D18: =IFERROR(__xludf.DUMMYFUNCTION("""COMPUTED_VALUE"""),60.0) -> 60 | E18: =IFERROR(__xludf.DUMMYFUNCTION("""COMPUTED_VALUE"""),50.0) -> 50 | F18: =IFERROR(__xludf.DUMMYFUNCTION("""COMPUTED_VALUE"""),"C. Ditolak") -> C. Ditolak | G18: =IFERROR(__xludf.DUMMYFUNCTION("""COMPUTED_VALUE"""),"Fuad Khomsatun") -> Fuad Khomsatun | H18: =IFERROR(__xludf.DUMMYFUNCTION("""COMPUTED_VALUE"""),"Makhroj, Tajwid, Kelancaran masih sangat jauh") -> Makhroj, Tajwid, Kelancaran masih sangat jauh | I18: =average(D18:E18) -> 55
A19: =IFERROR(__xludf.DUMMYFUNCTION("""COMPUTED_VALUE"""),"Abudzar Al Mahbub ") -> Abudzar Al Mahbub | B19: =IFERROR(__xludf.DUMMYFUNCTION("""COMPUTED_VALUE"""),"A250034") -> A250034 | C19: =IFERROR(__xludf.DUMMYFUNCTION("""COMPUTED_VALUE"""),"MTs Putra") -> MTs Putra | D19: =IFERROR(__xludf.DUMMYFUNCTION("""COMPUTED_VALUE"""),85.0) -> 85 | E19: =IFERROR(__xludf.DUMMYFUNCTION("""COMPUTED_VALUE"""),85.0) -> 85 | F19: =IFERROR(__xludf.DUMMYFUNCTION("""COMPUTED_VALUE"""),"A. Diterima") -> A. Diterima | G19: =IFERROR(__xludf.DUMMYFUNCTION("""COMPUTED_VALUE"""),"Fuad Khomsatun") -> Fuad Khomsatun | H19: =IFERROR(__xludf.DUMMYFUNCTION("""COMPUTED_VALUE"""),"makhroj, tajwid dan kelancaran okeeeee") -> makhroj, tajwid dan kelancaran okeeeee | I19: =average(D19:E19) -> 85
A20: =IFERROR(__xludf.DUMMYFUNCTION("""COMPUTED_VALUE"""),"Ksatria Hudzaifah Al Mizzi ") -> Ksatria Hudzaifah Al Mizzi | B20: =IFERROR(__xludf.DUMMYFUNCTION("""COMPUTED_VALUE"""),"B250010") -> B250010 | C20: =IFERROR(__xludf.DUMMYFUNCTION("""COMPUTED_VALUE"""),"IL Putra") -> IL Putra | D20: =IFERROR(__xludf.DUMMYFUNCTION("""COMPUTED_VALUE"""),95.0) -> 95 | E20: =IFERROR(__xludf.DUMMYFUNCTION("""COMPUTED_VALUE"""),90.0) -> 90 | F20: =IFERROR(__xludf.DUMMYFUNCTION("""COMPUTED_VALUE"""),"A. Diterima") -> A. Diterima | G20: =IFERROR(__xludf.DUMMYFUNCTION("""COMPUTED_VALUE"""),"Fuad Khomsatun") -> Fuad Khomsatun | H20: =IFERROR(__xludf.DUMMYFUNCTION("""COMPUTED_VALUE"""),"Paten bin Kongkrit ") -> Paten bin Kongkrit | I20: =average(D20:E20) -> 92.5
A21: =IFERROR(__xludf.DUMMYFUNCTION("""COMPUTED_VALUE"""),"FAEYZA IZZATUL KHAIRY") -> FAEYZA IZZATUL KHAIRY | B21: =IFERROR(__xludf.DUMMYFUNCTION("""COMPUTED_VALUE"""),"A250016") -> A250016 | C21: =IFERROR(__xludf.DUMMYFUNCTION("""COMPUTED_VALUE"""),"MTs Putra") -> MTs Putra | D21: =IFERROR(__xludf.DUMMYFUNCTION("""COMPUTED_VALUE"""),80.0) -> 80 | E21: =IFERROR(__xludf.DUMMYFUNCTION("""COMPUTED_VALUE"""),85.0) -> 85 | F21: =IFERROR(__xludf.DUMMYFUNCTION("""COMPUTED_VALUE"""),"B. Cadangan") -> B. Cadangan | G21: =IFERROR(__xludf.DUMMYFUNCTION("""COMPUTED_VALUE"""),"Agus Cahyono") -> Agus Cahyono | H21: =IFERROR(__xludf.DUMMYFUNCTION("""COMPUTED_VALUE"""),"- Secara umum ananda memiliki bacaan yang lancar, akan tetapi masih mengbaikan hukum tajwid yang berlaku - Terlalu lama menyebbut sebuah huruf sehingga banyak bacaan yang menjadi panjang") -> - Secara umum ananda memiliki bacaan yang lancar, akan tetapi masih mengbaikan hukum tajwid yang berlaku - Terlalu lama menyebbut sebuah huruf sehingga banyak bacaan yang menjadi panjang | I21: =average(D21:E21) -> 82.5
A22: =IFERROR(__xludf.DUMMYFUNCTION("""COMPUTED_VALUE"""),"Widya Meilani zahra ") -> Widya Meilani zahra | B22: =IFERROR(__xludf.DUMMYFUNCTION("""COMPUTED_VALUE"""),"E250001") -> E250001 | C22: =IFERROR(__xludf.DUMMYFUNCTION("""COMPUTED_VALUE"""),"IL Putri") -> IL Putri | D22: =IFERROR(__xludf.DUMMYFUNCTION("""COMPUTED_VALUE"""),85.0) -> 85 | E22: =IFERROR(__xludf.DUMMYFUNCTION("""COMPUTED_VALUE"""),90.0) -> 90 | F22: =IFERROR(__xludf.DUMMYFUNCTION("""COMPUTED_VALUE"""),"A. Diterima") -> A. Diterima | G22: =IFERROR(__xludf.DUMMYFUNCTION("""COMPUTED_VALUE"""),"Andi Fatimah Azzahra Rahman") -> Andi Fatimah Azzahra Rahman | I22: =average(D22:E22) -> 87.5
A23: =IFERROR(__xludf.DUMMYFUNCTION("""COMPUTED_VALUE"""),"Siti Hafsoh sholihah ") -> Siti Hafsoh sholihah | B23: =IFERROR(__xludf.DUMMYFUNCTION("""COMPUTED_VALUE"""),"E250005") -> E250005 | C23: =IFERROR(__xludf.DUMMYFUNCTION("""COMPUTED_VALUE"""),"IL Putri") -> IL Putri | D23: =IFERROR(__xludf.DUMMYFUNCTION("""COMPUTED_VALUE"""),85.0) -> 85 | E23: =IFERROR(__xludf.DUMMYFUNCTION("""COMPUTED_VALUE"""),90.0) -> 90 | F23: =IFERROR(__xludf.DUMMYFUNCTION("""COMPUTED_VALUE"""),"A. Diterima") -> A. Diterima | G23: =IFERROR(__xludf.DUMMYFUNCTION("""COMPUTED_VALUE"""),"Andi Fatimah Azzahra Rahman") -> Andi Fatimah Azzahra Rahman | I23: =average(D23:E23) -> 87.5
A24: =IFERROR(__xludf.DUMMYFUNCTION("""COMPUTED_VALUE"""),"Nadira Salsabila apriliani") -> Nadira Salsabila apriliani | B24: =IFERROR(__xludf.DUMMYFUNCTION("""COMPUTED_VALUE"""),"E250007") -> E250007 | C24: =IFERROR(__xludf.DUMMYFUNCTION("""COMPUTED_VALUE"""),"IL Putri") -> IL Putri | D24: =IFERROR(__xludf.DUMMYFUNCTION("""COMPUTED_VALUE"""),82.0) -> 82 | E24: =IFERROR(__xludf.DUMMYFUNCTION("""COMPUTED_VALUE"""),90.0) -> 90 | F24: =IFERROR(__xludf.DUMMYFUNCTION("""COMPUTED_VALUE"""),"A. Diterima") -> A. Diterima | G24: =IFERROR(__xludf.DUMMYFUNCTION("""COMPUTED_VALUE"""),"Andi Fatimah Azzahra Rahman") -> Andi Fatimah Azzahra Rahman | I24: =average(D24:E24) -> 86
A25: =IFERROR(__xludf.DUMMYFUNCTION("""COMPUTED_VALUE"""),"Hilda Sahlannisa") -> Hilda Sahlannisa | B25: =IFERROR(__xludf.DUMMYFUNCTION("""COMPUTED_VALUE"""),"E250002") -> E250002 | C25: =IFERROR(__xludf.DUMMYFUNCTION("""COMPUTED_VALUE"""),"IL Putri") -> IL Putri | D25: =IFERROR(__xludf.DUMMYFUNCTION("""COMPUTED_VALUE"""),84.0) -> 84 | E25: =IFERROR(__xludf.DUMMYFUNCTION("""COMPUTED_VALUE"""),90.0) -> 90 | F25: =IFERROR(__xludf.DUMMYFUNCTION("""COMPUTED_VALUE"""),"A. Diterima") -> A. Diterima | G25: =IFERROR(__xludf.DUMMYFUNCTION("""COMPUTED_VALUE"""),"Andi Fatimah Azzahra Rahman") -> Andi Fatimah Azzahra Rahman | I25: =average(D25:E25) -> 87
A26: =IFERROR(__xludf.DUMMYFUNCTION("""COMPUTED_VALUE"""),"SITI FATIMAH AZZAHRA") -> SITI FATIMAH AZZAHRA | B26: =IFERROR(__xludf.DUMMYFUNCTION("""COMPUTED_VALUE"""),"D250010") -> D250010 | C26: =IFERROR(__xludf.DUMMYFUNCTION("""COMPUTED_VALUE"""),"MTs Putri") -> MTs Putri | D26: =IFERROR(__xludf.DUMMYFUNCTION("""COMPUTED_VALUE"""),79.0) -> 79 | E26: =IFERROR(__xludf.DUMMYFUNCTION("""COMPUTED_VALUE"""),85.0) -> 85 | F26: =IFERROR(__xludf.DUMMYFUNCTION("""COMPUTED_VALUE"""),"A. Diterima") -> A. Diterima | G26: =IFERROR(__xludf.DUMMYFUNCTION("""COMPUTED_VALUE"""),"Andi Fatimah Azzahra Rahman") -> Andi Fatimah Azzahra Rahman | H26: =IFERROR(__xludf.DUMMYFUNCTION("""COMPUTED_VALUE"""),"Sebelum masuk pondok disarankan ada pembimbingan membaca al quran Agar lebih baik lagi") -> Sebelum masuk pondok disarankan ada pembimbingan membaca al quran Agar lebih baik lagi | I26: =average(D26:E26) -> 82
A27: =IFERROR(__xludf.DUMMYFUNCTION("""COMPUTED_VALUE"""),"Hanifah Qurrotul 'Ain ") -> Hanifah Qurrotul 'Ain | B27: =IFERROR(__xludf.DUMMYFUNCTION("""COMPUTED_VALUE"""),"D250002") -> D250002 | C27: =IFERROR(__xludf.DUMMYFUNCTION("""COMPUTED_VALUE"""),"MTs Putri") -> MTs Putri | D27: =IFERROR(__xludf.DUMMYFUNCTION("""COMPUTED_VALUE"""),87.0) -> 87 | E27: =IFERROR(__xludf.DUMMYFUNCTION("""COMPUTED_VALUE"""),92.0) -> 92 | F27: =IFERROR(__xludf.DUMMYFUNCTION("""COMPUTED_VALUE"""),"A. Diterima") -> A. Diterima | G27: =IFERROR(__xludf.DUMMYFUNCTION("""COMPUTED_VALUE"""),"Andi Fatimah Azzahra Rahman") -> Andi Fatimah Azzahra Rahman | I27: =average(D27:E27) -> 89.5
A28: =IFERROR(__xludf.DUMMYFUNCTION("""COMPUTED_VALUE"""),"Ulfia Nurfauziah ") -> Ulfia Nurfauziah | B28: =IFERROR(__xludf.DUMMYFUNCTION("""COMPUTED_VALUE"""),"D250027") -> D250027 | C28: =IFERROR(__xludf.DUMMYFUNCTION("""COMPUTED_VALUE"""),"MTs Putri") -> MTs Putri | D28: =IFERROR(__xludf.DUMMYFUNCTION("""COMPUTED_VALUE"""),85.0) -> 85 | E28: =IFERROR(__xludf.DUMMYFUNCTION("""COMPUTED_VALUE"""),90.0) -> 90 | F28: =IFERROR(__xludf.DUMMYFUNCTION("""COMPUTED_VALUE"""),"A. Diterima") -> A. Diterima | G28: =IFERROR(__xludf.DUMMYFUNCTION("""COMPUTED_VALUE"""),"Andi Fatimah Azzahra Rahman") -> Andi Fatimah Azzahra Rahman | I28: =average(D28:E28) -> 87.5
A29: =IFERROR(__xludf.DUMMYFUNCTION("""COMPUTED_VALUE"""),"Abu Reihan Al Fajri") -> Abu Reihan Al Fajri | B29: =IFERROR(__xludf.DUMMYFUNCTION("""COMPUTED_VALUE"""),"A250025") -> A250025 | C29: =IFERROR(__xludf.DUMMYFUNCTION("""COMPUTED_VALUE"""),"MTs Putra") -> MTs Putra | D29: =IFERROR(__xludf.DUMMYFUNCTION("""COMPUTED_VALUE"""),85.0) -> 85 | E29: =IFERROR(__xludf.DUMMYFUNCTION("""COMPUTED_VALUE"""),85.0) -> 85 | F29: =IFERROR(__xludf.DUMMYFUNCTION("""COMPUTED_VALUE"""),"A. Diterima") -> A. Diterima | G29: =IFERROR(__xludf.DUMMYFUNCTION("""COMPUTED_VALUE"""),"Jusman") -> Jusman | I29: =average(D29:E29) -> 85
A30: =IFERROR(__xludf.DUMMYFUNCTION("""COMPUTED_VALUE"""),"Satria Panca Desmara") -> Satria Panca Desmara | B30: =IFERROR(__xludf.DUMMYFUNCTION("""COMPUTED_VALUE"""),"A250028") -> A250028 | C30: =IFERROR(__xludf.DUMMYFUNCTION("""COMPUTED_VALUE"""),"MTs Putra") -> MTs Putra | D30: =IFERROR(__xludf.DUMMYFUNCTION("""COMPUTED_VALUE"""),70.0) -> 70 | E30: =IFERROR(__xludf.DUMMYFUNCTION("""COMPUTED_VALUE"""),73.0) -> 73 | F30: =IFERROR(__xludf.DUMMYFUNCTION("""COMPUTED_VALUE"""),"B. Cadangan") -> B. Cadangan | G30: =IFERROR(__xludf.DUMMYFUNCTION("""COMPUTED_VALUE"""),"Jusman") -> Jusman | H30: =IFERROR(__xludf.DUMMYFUNCTION("""COMPUTED_VALUE"""),"Perlu banyak belajar lagi, agar tidak banyak salah dalam membaca al-Qur'an") -> Perlu banyak belajar lagi, agar tidak banyak salah dalam membaca al-Qur'an | I30: =average(D30:E30) -> 71.5
A31: =IFERROR(__xludf.DUMMYFUNCTION("""COMPUTED_VALUE"""),"Keanu Azka Wibowo") -> Keanu Azka Wibowo | B31: =IFERROR(__xludf.DUMMYFUNCTION("""COMPUTED_VALUE"""),"B250021") -> B250021 | C31: =IFERROR(__xludf.DUMMYFUNCTION("""COMPUTED_VALUE"""),"IL Putra") -> IL Putra | D31: =IFERROR(__xludf.DUMMYFUNCTION("""COMPUTED_VALUE"""),90.0) -> 90 | E31: =IFERROR(__xludf.DUMMYFUNCTION("""COMPUTED_VALUE"""),93.0) -> 93 | F31: =IFERROR(__xludf.DUMMYFUNCTION("""COMPUTED_VALUE"""),"A. Diterima") -> A. Diterima | G31: =IFERROR(__xludf.DUMMYFUNCTION("""COMPUTED_VALUE"""),"Fuad Khomsatun") -> Fuad Khomsatun | H31: =IFERROR(__xludf.DUMMYFUNCTION("""COMPUTED_VALUE"""),"bagus kongkrit, tapi huruf Lam nya agak aneh dikit") -> bagus kongkrit, tapi huruf Lam nya agak aneh dikit | I31: =average(D31:E31) -> 91.5
A32: =IFERROR(__xludf.DUMMYFUNCTION("""COMPUTED_VALUE"""),"Muhammad Hanif Ash Shidiq") -> Muhammad Hanif Ash Shidiq | B32: =IFERROR(__xludf.DUMMYFUNCTION("""COMPUTED_VALUE"""),"A250048") -> A250048 | C32: =IFERROR(__xludf.DUMMYFUNCTION("""COMPUTED_VALUE"""),"MTs Putra") -> MTs Putra | D32: =IFERROR(__xludf.DUMMYFUNCTION("""COMPUTED_VALUE"""),90.0) -> 90 | E32: =IFERROR(__xludf.DUMMYFUNCTION("""COMPUTED_VALUE"""),87.0) -> 87 | F32: =IFERROR(__xludf.DUMMYFUNCTION("""COMPUTED_VALUE"""),"A. Diterima") -> A. Diterima | G32: =IFERROR(__xludf.DUMMYFUNCTION("""COMPUTED_VALUE"""),"Fuad Khomsatun") -> Fuad Khomsatun | H32: =IFERROR(__xludf.DUMMYFUNCTION("""COMPUTED_VALUE"""),"Paten bin Kongkrit") -> Paten bin Kongkrit | I32: =average(D32:E32) -> 88.5
A33: =IFERROR(__xludf.DUMMYFUNCTION("""COMPUTED_VALUE"""),"Nahnurizko Nabhan Faghali ") -> Nahnurizko Nabhan Faghali | B33: =IFERROR(__xludf.DUMMYFUNCTION("""COMPUTED_VALUE"""),"A250009") -> A250009 | C33: =IFERROR(__xludf.DUMMYFUNCTION("""COMPUTED_VALUE"""),"MTs Putra") -> MTs Putra | D33: =IFERROR(__xludf.DUMMYFUNCTION("""COMPUTED_VALUE"""),90.0) -> 90 | E33: =IFERROR(__xludf.DUMMYFUNCTION("""COMPUTED_VALUE"""),92.0) -> 92 | F33: =IFERROR(__xludf.DUMMYFUNCTION("""COMPUTED_VALUE"""),"A. Diterima") -> A. Diterima | G33: =IFERROR(__xludf.DUMMYFUNCTION("""COMPUTED_VALUE"""),"Fuad Khomsatun") -> Fuad Khomsatun | I33: =average(D33:E33) -> 91
A34: =IFERROR(__xludf.DUMMYFUNCTION("""COMPUTED_VALUE"""),"Nouvalldy Farzani Prayoga ") -> Nouvalldy Farzani Prayoga | B34: =IFERROR(__xludf.DUMMYFUNCTION("""COMPUTED_VALUE"""),"A250023") -> A250023 | C34: =IFERROR(__xludf.DUMMYFUNCTION("""COMPUTED_VALUE"""),"MTs Putra") -> MTs Putra | D34: =IFERROR(__xludf.DUMMYFUNCTION("""COMPUTED_VALUE"""),60.0) -> 60 | E34: =IFERROR(__xludf.DUMMYFUNCTION("""COMPUTED_VALUE"""),58.0) -> 58 | F34: =IFERROR(__xludf.DUMMYFUNCTION("""COMPUTED_VALUE"""),"C. Ditolak") -> C. Ditolak | G34: =IFERROR(__xludf.DUMMYFUNCTION("""COMPUTED_VALUE"""),"Fuad Khomsatun") -> Fuad Khomsatun | H34: =IFERROR(__xludf.DUMMYFUNCTION("""COMPUTED_VALUE"""),"lumayan jauh tertinggaln") -> lumayan jauh tertinggaln | I34: =average(D34:E34) -> 59
A35: =IFERROR(__xludf.DUMMYFUNCTION("""COMPUTED_VALUE"""),"Muhammad Arkan") -> Muhammad Arkan | B35: =IFERROR(__xludf.DUMMYFUNCTION("""COMPUTED_VALUE"""),"A250037") -> A250037 | C35: =IFERROR(__xludf.DUMMYFUNCTION("""COMPUTED_VALUE"""),"MTs Putra") -> MTs Putra | D35: =IFERROR(__xludf.DUMMYFUNCTION("""COMPUTED_VALUE"""),90.0) -> 90 | E35: =IFERROR(__xludf.DUMMYFUNCTION("""COMPUTED_VALUE"""),95.0) -> 95 | F35: =IFERROR(__xludf.DUMMYFUNCTION("""COMPUTED_VALUE"""),"A. Diterima") -> A. Diterima | G35: =IFERROR(__xludf.DUMMYFUNCTION("""COMPUTED_VALUE"""),"Agus Cahyono") -> Agus Cahyono | H35: =IFERROR(__xludf.DUMMYFUNCTION("""COMPUTED_VALUE"""),"Alhamdulillah") -> Alhamdulillah | I35: =average(D35:E35) -> 92.5
A36: =IFERROR(__xludf.DUMMYFUNCTION("""COMPUTED_VALUE"""),"Sulthan Faqih Al Hadziq") -> Sulthan Faqih Al Hadziq | B36: =IFERROR(__xludf.DUMMYFUNCTION("""COMPUTED_VALUE"""),"A250046") -> A250046 | C36: =IFERROR(__xludf.DUMMYFUNCTION("""COMPUTED_VALUE"""),"MTs Putra") -> MTs Putra | D36: =IFERROR(__xludf.DUMMYFUNCTION("""COMPUTED_VALUE"""),93.0) -> 93 | E36: =IFERROR(__xludf.DUMMYFUNCTION("""COMPUTED_VALUE"""),95.0) -> 95 | F36: =IFERROR(__xludf.DUMMYFUNCTION("""COMPUTED_VALUE"""),"A. Diterima") -> A. Diterima | G36: =IFERROR(__xludf.DUMMYFUNCTION("""COMPUTED_VALUE"""),"Agus Cahyono") -> Agus Cahyono | H36: =IFERROR(__xludf.DUMMYFUNCTION("""COMPUTED_VALUE"""),"Alhamdulillah") -> Alhamdulillah | I36: =average(D36:E36) -> 94
A37: =IFERROR(__xludf.DUMMYFUNCTION("""COMPUTED_VALUE"""),"Muhammad Umar Ali ") -> Muhammad Umar Ali | B37: =IFERROR(__xludf.DUMMYFUNCTION("""COMPUTED_VALUE"""),"A250020") -> A250020 | C37: =IFERROR(__xludf.DUMMYFUNCTION("""COMPUTED_VALUE"""),"MTs Putra") -> MTs Putra | D37: =IFERROR(__xludf.DUMMYFUNCTION("""COMPUTED_VALUE"""),78.0) -> 78 | E37: =IFERROR(__xludf.DUMMYFUNCTION("""COMPUTED_VALUE"""),75.0) -> 75 | F37: =IFERROR(__xludf.DUMMYFUNCTION("""COMPUTED_VALUE"""),"B. Cadangan") -> B. Cadangan | G37: =IFERROR(__xludf.DUMMYFUNCTION("""COMPUTED_VALUE"""),"Fuad Khomsatun") -> Fuad Khomsatun | H37: =IFERROR(__xludf.DUMMYFUNCTION("""COMPUTED_VALUE"""),"makhroj lumayan bagus, mad dan ghunnah tidak terlalu parah. Tapi kelimpungan dalam membaca pada beberapa kalimat dalam Al Qur'an ") -> makhroj lumayan bagus, mad dan ghunnah tidak terlalu parah. Tapi kelimpungan dalam membaca pada beberapa kalimat dalam Al Qur'an | I37: =average(D37:E37) -> 76.5
A38: =IFERROR(__xludf.DUMMYFUNCTION("""COMPUTED_VALUE"""),"Muhammad Usman Ali") -> Muhammad Usman Ali | B38: =IFERROR(__xludf.DUMMYFUNCTION("""COMPUTED_VALUE"""),"A250018") -> A250018 | C38: =IFERROR(__xludf.DUMMYFUNCTION("""COMPUTED_VALUE"""),"MTs Putra") -> MTs Putra | D38: =IFERROR(__xludf.DUMMYFUNCTION("""COMPUTED_VALUE"""),65.0) -> 65 | E38: =IFERROR(__xludf.DUMMYFUNCTION("""COMPUTED_VALUE"""),60.0) -> 60 | F38: =IFERROR(__xludf.DUMMYFUNCTION("""COMPUTED_VALUE"""),"C. Ditolak") -> C. Ditolak | G38: =IFERROR(__xludf.DUMMYFUNCTION("""COMPUTED_VALUE"""),"Fuad Khomsatun") -> Fuad Khomsatun | H38: =IFERROR(__xludf.DUMMYFUNCTION("""COMPUTED_VALUE"""),"Kalo makhroj lumayan, tapi tajwid dan kelancaran kurang konkret. Berbeda dgn Umar ") -> Kalo makhroj lumayan, tapi tajwid dan kelancaran kurang konkret. Berbeda dgn Umar | I38: =average(D38:E38) -> 62.5
A39: =IFERROR(__xludf.DUMMYFUNCTION("""COMPUTED_VALUE"""),"Muhammad Hilmy Ilyasa Rizal") -> Muhammad Hilmy Ilyasa Rizal | B39: =IFERROR(__xludf.DUMMYFUNCTION("""COMPUTED_VALUE"""),"A250014") -> A250014 | C39: =IFERROR(__xludf.DUMMYFUNCTION("""COMPUTED_VALUE"""),"MTs Putra") -> MTs Putra | D39: =IFERROR(__xludf.DUMMYFUNCTION("""COMPUTED_VALUE"""),87.0) -> 87 | E39: =IFERROR(__xludf.DUMMYFUNCTION("""COMPUTED_VALUE"""),85.0) -> 85 | F39: =IFERROR(__xludf.DUMMYFUNCTION("""COMPUTED_VALUE"""),"A. Diterima") -> A. Diterima | G39: =IFERROR(__xludf.DUMMYFUNCTION("""COMPUTED_VALUE"""),"Agus Cahyono") -> Agus Cahyono | H39: =IFERROR(__xludf.DUMMYFUNCTION("""COMPUTED_VALUE"""),"1. Ananda Kurang teliti ketika membaca. ") -> 1. Ananda Kurang teliti ketika membaca. | I39: =average(D39:E39) -> 86
A40: =IFERROR(__xludf.DUMMYFUNCTION("""COMPUTED_VALUE"""),"Wahid Ahmad Nugraha") -> Wahid Ahmad Nugraha | B40: =IFERROR(__xludf.DUMMYFUNCTION("""COMPUTED_VALUE"""),"A250043") -> A250043 | C40: =IFERROR(__xludf.DUMMYFUNCTION("""COMPUTED_VALUE"""),"MTs Putra") -> MTs Putra | D40: =IFERROR(__xludf.DUMMYFUNCTION("""COMPUTED_VALUE"""),80.0) -> 80 | E40: =IFERROR(__xludf.DUMMYFUNCTION("""COMPUTED_VALUE"""),75.0) -> 75 | F40: =IFERROR(__xludf.DUMMYFUNCTION("""COMPUTED_VALUE"""),"B. Cadangan") -> B. Cadangan | G40: =IFERROR(__xludf.DUMMYFUNCTION("""COMPUTED_VALUE"""),"Jusman") -> Jusman | H40: =IFERROR(__xludf.DUMMYFUNCTION("""COMPUTED_VALUE"""),"Terus belajar dan dilatih terus lisannya dengan memperbanyak baca Al-Qur'an") -> Terus belajar dan dilatih terus lisannya dengan memperbanyak baca Al-Qur'an | I40: =average(D40:E40) -> 77.5
...

Sheet A.M
F1: 1 | G1: 2 | H1: 3 | I1: 4 | J1: 5 | K1: 6 | L1: 7 | M1: 8 | N1: 9 | O1: 10 | P1: 11 | Q1: 12 | R1: 13 | S1: 14 | T1: 15 | U1: 16 | V1: 17 | W1: 18 | X1: 19 | Y1: 20 | Z1: PAI | AF1: Bahasa Indonesia | AL1: IPA | AR1: Matematika
A2: Tanggal | B2: Nama Lengkap | C2: No. Pendaftaran | D2: Jenjang | E2: Kejujuran | F2: 1 | G2: 2 | H2: 3 | I2: 4 | J2: 5 | K2: 6 | L2: 7 | M2: 8 | N2: 9 | O2: 10 | P2: 11 | Q2: 12 | R2: 13 | S2: 14 | T2: 15 | U2: 16 | V2: 17 | W2: 18 | X2: 19 | Y2: 20 | Z2: 1 | AA2: 2 | AB2: 3 | AC2: 4 | AD2: 5 | AE2: Nilai | AF2: 6 | AG2: 7 | AH2: 8 | AI2: 9 | AJ2: 10 | AK2: Nilai | AL2: 11 | AM2: 12 | AN2: 13 | AO2: 14 | AP2: 15 | AQ2: Nilai | AR2: 16 | AS2: 17 | AT2: 18 | AU2: 19 | AV2: 20 | AW2: Nilai | AY2: PAI | AZ2: B. Ind | BA2: IPA | BB2: MTK
A3: =IFERROR(__xludf.DUMMYFUNCTION("IMPORTRANGE(""https://docs.google.com/spreadsheets/d/1w4NXg816eI7tg1xm3s4iZpgFUIQ3GERl7LlMfsuXt9c/edit?resourcekey=&gid=1083019139#gid=1083019139"",""Form Responses 1!A2:Y1000"")"),"") | Z3: =IF(F3="B. Aku bersaksi bahwa tidak ada tuhan yang berhak di sembah kecuali Allah",1,0) -> 0 | AA3: =IF(G3=6,1,0) -> 0 | AB3: =IF(H3="1 Syawwal",1,0) -> 0 | AC3: =IF(I3="Al 'Alaq",1,0) -> 0 | AD3: =IF(J3="Ali Bin Abi Thalib",1,0) -> 0 | AE3: =sum(Z3:AD3) -> 0 | AF3: =IF(K3="giat",1,0) -> 0 | AG3: =IF(L3="dan",1,0) -> 0 | AH3: =IF(M3="Hafsah mengatakan bahwa ia ingin belajar di pesantren.",1,0) -> 0 | AI3: =IF(N3="Kalimat 1",1,0) -> 0 | AJ3: =IF(O3="cahaya",1,0) -> 0 | AK3: =sum(AF3:AJ3) -> 0 | AL3: =IF(P3="Parasitisme",1,0) -> 0 | AM3: =IF(Q3="Angin",1,0) -> 0 | AN3: =IF(R3="belalang dan ular",1,0) -> 0 | AO3: =IF(S3="Menghasilkan klorofil",1,0) -> 0 | AP3: =IF(T3="Kelinci",1,0) -> 0 | AQ3: =sum(AL3:AP3) -> 0 | AR3: =IF(U3=-64,1,0) -> 0 | AS3: =IF(V3="3/4",1,0) -> 0 | AT3: =IF(W3="1.800 meter",1,0) -> 0 | AU3: =IF(X3="22 cm",1,0) -> 0 | AV3: =IF(Y3="200",1,0) -> 0 | AW3: =sum(AR3:AV3) -> 0 | AY3: =AE3 -> 0 | AZ3: =AK3 -> 0 | BA3: =AQ3 -> 0 | BB3: =AW3 -> 0 | BC3: =sum(AY3:BB3)*5 -> 0
A4: =IFERROR(__xludf.DUMMYFUNCTION("""COMPUTED_VALUE"""),45918.54390133102) -> 45918.544 | B4: =IFERROR(__xludf.DUMMYFUNCTION("""COMPUTED_VALUE"""),"Aviccena syahdan haqqani ") -> Aviccena syahdan haqqani | C4: =IFERROR(__xludf.DUMMYFUNCTION("""COMPUTED_VALUE"""),"A250060") -> A250060 | D4: =IFERROR(__xludf.DUMMYFUNCTION("""COMPUTED_VALUE"""),"MTs Putra") -> MTs Putra | E4: =IFERROR(__xludf.DUMMYFUNCTION("""COMPUTED_VALUE"""),"Ya") -> Ya | F4: =IFERROR(__xludf.DUMMYFUNCTION("""COMPUTED_VALUE"""),"B. Aku bersaksi bahwa tidak ada tuhan yang berhak di sembah kecuali Allah") -> B. Aku bersaksi bahwa tidak ada tuhan yang berhak di sembah kecuali Allah | G4: =IFERROR(__xludf.DUMMYFUNCTION("""COMPUTED_VALUE"""),6.0) -> 6 | H4: =IFERROR(__xludf.DUMMYFUNCTION("""COMPUTED_VALUE"""),"1 Syawwal") -> 1 Syawwal | I4: =IFERROR(__xludf.DUMMYFUNCTION("""COMPUTED_VALUE"""),"Al 'Alaq") -> Al 'Alaq | J4: =IFERROR(__xludf.DUMMYFUNCTION("""COMPUTED_VALUE"""),"Ali Bin Abi Thalib") -> Ali Bin Abi Thalib | K4: =IFERROR(__xludf.DUMMYFUNCTION("""COMPUTED_VALUE"""),"giat") -> giat | L4: =IFERROR(__xludf.DUMMYFUNCTION("""COMPUTED_VALUE"""),"dan") -> dan | M4: =IFERROR(__xludf.DUMMYFUNCTION("""COMPUTED_VALUE"""),"Aku berkata Hafsah ingin belajar di pesantren.") -> Aku berkata Hafsah ingin belajar di pesantren. | N4: =IFERROR(__xludf.DUMMYFUNCTION("""COMPUTED_VALUE"""),"Kalimat 1") -> Kalimat 1 | O4: =IFERROR(__xludf.DUMMYFUNCTION("""COMPUTED_VALUE"""),"cahaya") -> cahaya | P4: =IFERROR(__xludf.DUMMYFUNCTION("""COMPUTED_VALUE"""),"Komensalisme") -> Komensalisme | Q4: =IFERROR(__xludf.DUMMYFUNCTION("""COMPUTED_VALUE"""),"Angin") -> Angin | R4: =IFERROR(__xludf.DUMMYFUNCTION("""COMPUTED_VALUE"""),"pipit dan burung hantu") -> pipit dan burung hantu | S4: =IFERROR(__xludf.DUMMYFUNCTION("""COMPUTED_VALUE"""),"Adanya pertulangan daun") -> Adanya pertulangan daun | T4: =IFERROR(__xludf.DUMMYFUNCTION("""COMPUTED_VALUE"""),"Kadal") -> Kadal | U4: =IFERROR(__xludf.DUMMYFUNCTION("""COMPUTED_VALUE"""),56.0) -> 56 | V4: =IFERROR(__xludf.DUMMYFUNCTION("""COMPUTED_VALUE"""),"3/4") -> 3/4 | W4: =IFERROR(__xludf.DUMMYFUNCTION("""COMPUTED_VALUE"""),"1.250 meter") -> 1.250 meter | X4: =IFERROR(__xludf.DUMMYFUNCTION("""COMPUTED_VALUE"""),"11 cm") -> 11 cm | Y4: =IFERROR(__xludf.DUMMYFUNCTION("""COMPUTED_VALUE"""),1000.0) -> 1000 | Z4: =IF(F4="B. Aku bersaksi bahwa tidak ada tuhan yang berhak di sembah kecuali Allah",1,0) -> 1 | AA4: =IF(G4=6,1,0) -> 1 | AB4: =IF(H4="1 Syawwal",1,0) -> 1 | AC4: =IF(I4="Al 'Alaq",1,0) -> 1 | AD4: =IF(J4="Ali Bin Abi Thalib",1,0) -> 1 | AE4: =sum(Z4:AD4) -> 5 | AF4: =IF(K4="giat",1,0) -> 1 | AG4: =IF(L4="dan",1,0) -> 1 | AH4: =IF(M4="Hafsah mengatakan bahwa ia ingin belajar di pesantren.",1,0) -> 0 | AI4: =IF(N4="Kalimat 1",1,0) -> 1 | AJ4: =IF(O4="cahaya",1,0) -> 1 | AK4: =sum(AF4:AJ4) -> 4 | AL4: =IF(P4="Parasitisme",1,0) -> 0 | AM4: =IF(Q4="Angin",1,0) -> 1 | AN4: =IF(R4="belalang dan ular",1,0) -> 0 | AO4: =IF(S4="Menghasilkan klorofil",1,0) -> 0 | AP4: =IF(T4="Kelinci",1,0) -> 0 | AQ4: =sum(AL4:AP4) -> 1 | AR4: =IF(U4=-64,1,0) -> 0 | AS4: =IF(V4="3/4",1,0) -> 1 | AT4: =IF(W4="1.800 meter",1,0) -> 0 | AU4: =IF(X4="22 cm",1,0) -> 0 | AV4: =IF(Y4="200",1,0) -> 0 | AW4: =sum(AR4:AV4) -> 1 | AY4: =AE4 -> 5 | AZ4: =AK4 -> 4 | BA4: =AQ4 -> 1 | BB4: =AW4 -> 1 | BC4: =sum(AY4:BB4)*5 -> 55
A5: =IFERROR(__xludf.DUMMYFUNCTION("""COMPUTED_VALUE"""),45919.839533148144) -> 45919.84 | B5: =IFERROR(__xludf.DUMMYFUNCTION("""COMPUTED_VALUE"""),"Daffa Taamir Alfarizi ") -> Daffa Taamir Alfarizi | C5: =IFERROR(__xludf.DUMMYFUNCTION("""COMPUTED_VALUE"""),"A250008") -> A250008 | D5: =IFERROR(__xludf.DUMMYFUNCTION("""COMPUTED_VALUE"""),"MTs Putra") -> MTs Putra | E5: =IFERROR(__xludf.DUMMYFUNCTION("""COMPUTED_VALUE"""),"Ya") -> Ya | F5: =IFERROR(__xludf.DUMMYFUNCTION("""COMPUTED_VALUE"""),"B. Aku bersaksi bahwa tidak ada tuhan yang berhak di sembah kecuali Allah") -> B. Aku bersaksi bahwa tidak ada tuhan yang berhak di sembah kecuali Allah | G5: =IFERROR(__xludf.DUMMYFUNCTION("""COMPUTED_VALUE"""),6.0) -> 6 | H5: =IFERROR(__xludf.DUMMYFUNCTION("""COMPUTED_VALUE"""),"1 Syawwal") -> 1 Syawwal | I5: =IFERROR(__xludf.DUMMYFUNCTION("""COMPUTED_VALUE"""),"Al 'Alaq") -> Al 'Alaq | J5: =IFERROR(__xludf.DUMMYFUNCTION("""COMPUTED_VALUE"""),"Ali Bin Abi Thalib") -> Ali Bin Abi Thalib | K5: =IFERROR(__xludf.DUMMYFUNCTION("""COMPUTED_VALUE"""),"giat") -> giat | L5: =IFERROR(__xludf.DUMMYFUNCTION("""COMPUTED_VALUE"""),"dan") -> dan | M5: =IFERROR(__xludf.DUMMYFUNCTION("""COMPUTED_VALUE"""),"Hafsah mengatakan bahwa ia ingin belajar di pesantren.") -> Hafsah mengatakan bahwa ia ingin belajar di pesantren. | N5: =IFERROR(__xludf.DUMMYFUNCTION("""COMPUTED_VALUE"""),"Kalimat 1") -> Kalimat 1 | O5: =IFERROR(__xludf.DUMMYFUNCTION("""COMPUTED_VALUE"""),"kehidupan") -> kehidupan | P5: =IFERROR(__xludf.DUMMYFUNCTION("""COMPUTED_VALUE"""),"Parasitisme") -> Parasitisme | Q5: =IFERROR(__xludf.DUMMYFUNCTION("""COMPUTED_VALUE"""),"Angin") -> Angin | R5: =IFERROR(__xludf.DUMMYFUNCTION("""COMPUTED_VALUE"""),"belalang dan ular") -> belalang dan ular | S5: =IFERROR(__xludf.DUMMYFUNCTION("""COMPUTED_VALUE"""),"Menghasilkan klorofil") -> Menghasilkan klorofil | T5: =IFERROR(__xludf.DUMMYFUNCTION("""COMPUTED_VALUE"""),"Kelinci") -> Kelinci | U5: =IFERROR(__xludf.DUMMYFUNCTION("""COMPUTED_VALUE"""),-64.0) -> -64 | V5: =IFERROR(__xludf.DUMMYFUNCTION("""COMPUTED_VALUE"""),"3/4") -> 3/4 | W5: =IFERROR(__xludf.DUMMYFUNCTION("""COMPUTED_VALUE"""),"1.800 meter") -> 1.800 meter | X5: =IFERROR(__xludf.DUMMYFUNCTION("""COMPUTED_VALUE"""),"22 cm") -> 22 cm | Y5: =IFERROR(__xludf.DUMMYFUNCTION("""COMPUTED_VALUE"""),200.0) -> 200 | Z5: =IF(F5="B. Aku bersaksi bahwa tidak ada tuhan yang berhak di sembah kecuali Allah",1,0) -> 1 | AA5: =IF(G5=6,1,0) -> 1 | AB5: =IF(H5="1 Syawwal",1,0) -> 1 | AC5: =IF(I5="Al 'Alaq",1,0) -> 1 | AD5: =IF(J5="Ali Bin Abi Thalib",1,0) -> 1 | AE5: =sum(Z5:AD5) -> 5 | AF5: =IF(K5="giat",1,0) -> 1 | AG5: =IF(L5="dan",1,0) -> 1 | AH5: =IF(M5="Hafsah mengatakan bahwa ia ingin belajar di pesantren.",1,0) -> 1 | AI5: =IF(N5="Kalimat 1",1,0) -> 1 | AJ5: =IF(O5="cahaya",1,0) -> 0 | AK5: =sum(AF5:AJ5) -> 4 | AL5: =IF(P5="Parasitisme",1,0) -> 1 | AM5: =IF(Q5="Angin",1,0) -> 1 | AN5: =IF(R5="belalang dan ular",1,0) -> 1 | AO5: =IF(S5="Menghasilkan klorofil",1,0) -> 1 | AP5: =IF(T5="Kelinci",1,0) -> 1 | AQ5: =sum(AL5:AP5) -> 5 | AR5: =IF(U5=-64,1,0) -> 1 | AS5: =IF(V5="3/4",1,0) -> 1 | AT5: =IF(W5="1.800 meter",1,0) -> 1 | AU5: =IF(X5="22 cm",1,0) -> 1 | AV5: =IF(Y5="200",1,0) -> 0 | AW5: =sum(AR5:AV5) -> 4 | AY5: =AE5 -> 5 | AZ5: =AK5 -> 4 | BA5: =AQ5 -> 5 | BB5: =AW5 -> 4 | BC5: =sum(AY5:BB5)*5 -> 90
A6: =IFERROR(__xludf.DUMMYFUNCTION("""COMPUTED_VALUE"""),45920.35915685185) -> 45920.359 | B6: =IFERROR(__xludf.DUMMYFUNCTION("""COMPUTED_VALUE"""),"keyza qaireen") -> keyza qaireen | C6: =IFERROR(__xludf.DUMMYFUNCTION("""COMPUTED_VALUE"""),"D250009") -> D250009 | D6: =IFERROR(__xludf.DUMMYFUNCTION("""COMPUTED_VALUE"""),"MTs Putri") -> MTs Putri | E6: =IFERROR(__xludf.DUMMYFUNCTION("""COMPUTED_VALUE"""),"Ya") -> Ya | F6: =IFERROR(__xludf.DUMMYFUNCTION("""COMPUTED_VALUE"""),"B. Aku bersaksi bahwa tidak ada tuhan yang berhak di sembah kecuali Allah") -> B. Aku bersaksi bahwa tidak ada tuhan yang berhak di sembah kecuali Allah | G6: =IFERROR(__xludf.DUMMYFUNCTION("""COMPUTED_VALUE"""),6.0) -> 6 | H6: =IFERROR(__xludf.DUMMYFUNCTION("""COMPUTED_VALUE"""),"1 Syawwal") -> 1 Syawwal | I6: =IFERROR(__xludf.DUMMYFUNCTION("""COMPUTED_VALUE"""),"Al 'Alaq") -> Al 'Alaq | J6: =IFERROR(__xludf.DUMMYFUNCTION("""COMPUTED_VALUE"""),"Utsman Bin Affan") -> Utsman Bin Affan | K6: =IFERROR(__xludf.DUMMYFUNCTION("""COMPUTED_VALUE"""),"malas") -> malas | L6: =IFERROR(__xludf.DUMMYFUNCTION("""COMPUTED_VALUE"""),"dan") -> dan | M6: =IFERROR(__xludf.DUMMYFUNCTION("""COMPUTED_VALUE"""),"Hafsah mengatakan bahwa aku ingin belajar di pesantren.") -> Hafsah mengatakan bahwa aku ingin belajar di pesantren. | N6: =IFERROR(__xludf.DUMMYFUNCTION("""COMPUTED_VALUE"""),"Kalimat 1") -> Kalimat 1 | O6: =IFERROR(__xludf.DUMMYFUNCTION("""COMPUTED_VALUE"""),"cahaya") -> cahaya | P6: =IFERROR(__xludf.DUMMYFUNCTION("""COMPUTED_VALUE"""),"Parasitisme") -> Parasitisme | Q6: =IFERROR(__xludf.DUMMYFUNCTION("""COMPUTED_VALUE"""),"Angin") -> Angin | R6: =IFERROR(__xludf.DUMMYFUNCTION("""COMPUTED_VALUE"""),"belalang dan ular") -> belalang dan ular | S6: =IFERROR(__xludf.DUMMYFUNCTION("""COMPUTED_VALUE"""),"Daun yang pipih dan lebar") -> Daun yang pipih dan lebar | T6: =IFERROR(__xludf.DUMMYFUNCTION("""COMPUTED_VALUE"""),"Buaya") -> Buaya | U6: =IFERROR(__xludf.DUMMYFUNCTION("""COMPUTED_VALUE"""),-64.0) -> -64 | V6: =IFERROR(__xludf.DUMMYFUNCTION("""COMPUTED_VALUE"""),"3/4") -> 3/4 | W6: =IFERROR(__xludf.DUMMYFUNCTION("""COMPUTED_VALUE"""),"1.800 meter") -> 1.800 meter | X6: =IFERROR(__xludf.DUMMYFUNCTION("""COMPUTED_VALUE"""),"22 cm") -> 22 cm | Y6: =IFERROR(__xludf.DUMMYFUNCTION("""COMPUTED_VALUE"""),200.0) -> 200 | Z6: =IF(F6="B. Aku bersaksi bahwa tidak ada tuhan yang berhak di sembah kecuali Allah",1,0) -> 1 | AA6: =IF(G6=6,1,0) -> 1 | AB6: =IF(H6="1 Syawwal",1,0) -> 1 | AC6: =IF(I6="Al 'Alaq",1,0) -> 1 | AD6: =IF(J6="Ali Bin Abi Thalib",1,0) -> 0 | AE6: =sum(Z6:AD6) -> 4 | AF6: =IF(K6="giat",1,0) -> 0 | AG6: =IF(L6="dan",1,0) -> 1 | AH6: =IF(M6="Hafsah mengatakan bahwa ia ingin belajar di pesantren.",1,0) -> 0 | AI6: =IF(N6="Kalimat 1",1,0) -> 1 | AJ6: =IF(O6="cahaya",1,0) -> 1 | AK6: =sum(AF6:AJ6) -> 3 | AL6: =IF(P6="Parasitisme",1,0) -> 1 | AM6: =IF(Q6="Angin",1,0) -> 1 | AN6: =IF(R6="belalang dan ular",1,0) -> 1 | AO6: =IF(S6="Menghasilkan klorofil",1,0) -> 0 | AP6: =IF(T6="Kelinci",1,0) -> 0 | AQ6: =sum(AL6:AP6) -> 3 | AR6: =IF(U6=-64,1,0) -> 1 | AS6: =IF(V6="3/4",1,0) -> 1 | AT6: =IF(W6="1.800 meter",1,0) -> 1 | AU6: =IF(X6="22 cm",1,0) -> 1 | AV6: =IF(Y6="200",1,0) -> 0 | AW6: =sum(AR6:AV6) -> 4 | AY6: =AE6 -> 4 | AZ6: =AK6 -> 3 | BA6: =AQ6 -> 3 | BB6: =AW6 -> 4 | BC6: =sum(AY6:BB6)*5 -> 70
A7: =IFERROR(__xludf.DUMMYFUNCTION("""COMPUTED_VALUE"""),45920.4010121875) -> 45920.401 | B7: =IFERROR(__xludf.DUMMYFUNCTION("""COMPUTED_VALUE"""),"Siti Azizah") -> Siti Azizah | C7: =IFERROR(__xludf.DUMMYFUNCTION("""COMPUTED_VALUE"""),"D250007") -> D250007 | D7: =IFERROR(__xludf.DUMMYFUNCTION("""COMPUTED_VALUE"""),"MTs Putri") -> MTs Putri | E7: =IFERROR(__xludf.DUMMYFUNCTION("""COMPUTED_VALUE"""),"Ya") -> Ya | F7: =IFERROR(__xludf.DUMMYFUNCTION("""COMPUTED_VALUE"""),"B. Aku bersaksi bahwa tidak ada tuhan yang berhak di sembah kecuali Allah") -> B. Aku bersaksi bahwa tidak ada tuhan yang berhak di sembah kecuali Allah | G7: =IFERROR(__xludf.DUMMYFUNCTION("""COMPUTED_VALUE"""),6.0) -> 6 | H7: =IFERROR(__xludf.DUMMYFUNCTION("""COMPUTED_VALUE"""),"1 Syawwal") -> 1 Syawwal | I7: =IFERROR(__xludf.DUMMYFUNCTION("""COMPUTED_VALUE"""),"Al 'Alaq") -> Al 'Alaq | J7: =IFERROR(__xludf.DUMMYFUNCTION("""COMPUTED_VALUE"""),"Abu Bakar Ash Shiddiiq") -> Abu Bakar Ash Shiddiiq | K7: =IFERROR(__xludf.DUMMYFUNCTION("""COMPUTED_VALUE"""),"giat") -> giat | L7: =IFERROR(__xludf.DUMMYFUNCTION("""COMPUTED_VALUE"""),"dan") -> dan | M7: =IFERROR(__xludf.DUMMYFUNCTION("""COMPUTED_VALUE"""),"Hafsah mengatakan bahwa ia ingin belajar di pesantren.") -> Hafsah mengatakan bahwa ia ingin belajar di pesantren. | N7: =IFERROR(__xludf.DUMMYFUNCTION("""COMPUTED_VALUE"""),"Kalimat 1") -> Kalimat 1 | O7: =IFERROR(__xludf.DUMMYFUNCTION("""COMPUTED_VALUE"""),"cahaya") -> cahaya | P7: =IFERROR(__xludf.DUMMYFUNCTION("""COMPUTED_VALUE"""),"Parasitisme") -> Parasitisme | Q7: =IFERROR(__xludf.DUMMYFUNCTION("""COMPUTED_VALUE"""),"Angin") -> Angin | R7: =IFERROR(__xludf.DUMMYFUNCTION("""COMPUTED_VALUE"""),"belalang dan ular") -> belalang dan ular | S7: =IFERROR(__xludf.DUMMYFUNCTION("""COMPUTED_VALUE"""),"Daun yang pipih dan lebar") -> Daun yang pipih dan lebar | T7: =IFERROR(__xludf.DUMMYFUNCTION("""COMPUTED_VALUE"""),"Kadal") -> Kadal | U7: =IFERROR(__xludf.DUMMYFUNCTION("""COMPUTED_VALUE"""),-64.0) -> -64 | V7: =IFERROR(__xludf.DUMMYFUNCTION("""COMPUTED_VALUE"""),1.0) -> 1 | W7: =IFERROR(__xludf.DUMMYFUNCTION("""COMPUTED_VALUE"""),"1.800 meter") -> 1.800 meter | X7: =IFERROR(__xludf.DUMMYFUNCTION("""COMPUTED_VALUE"""),"28 cm") -> 28 cm | Y7: =IFERROR(__xludf.DUMMYFUNCTION("""COMPUTED_VALUE"""),200.0) -> 200 | Z7: =IF(F7="B. Aku bersaksi bahwa tidak ada tuhan yang berhak di sembah kecuali Allah",1,0) -> 1 | AA7: =IF(G7=6,1,0) -> 1 | AB7: =IF(H7="1 Syawwal",1,0) -> 1 | AC7: =IF(I7="Al 'Alaq",1,0) -> 1 | AD7: =IF(J7="Ali Bin Abi Thalib",1,0) -> 0 | AE7: =sum(Z7:AD7) -> 4 | AF7: =IF(K7="giat",1,0) -> 1 | AG7: =IF(L7="dan",1,0) -> 1 | AH7: =IF(M7="Hafsah mengatakan bahwa ia ingin belajar di pesantren.",1,0) -> 1 | AI7: =IF(N7="Kalimat 1",1,0) -> 1 | AJ7: =IF(O7="cahaya",1,0) -> 1 | AK7: =sum(AF7:AJ7) -> 5 | AL7: =IF(P7="Parasitisme",1,0) -> 1 | AM7: =IF(Q7="Angin",1,0) -> 1 | AN7: =IF(R7="belalang dan ular",1,0) -> 1 | AO7: =IF(S7="Menghasilkan klorofil",1,0) -> 0 | AP7: =IF(T7="Kelinci",1,0) -> 0 | AQ7: =sum(AL7:AP7) -> 3 | AR7: =IF(U7=-64,1,0) -> 1 | AS7: =IF(V7="3/4",1,0) -> 0 | AT7: =IF(W7="1.800 meter",1,0) -> 1 | AU7: =IF(X7="22 cm",1,0) -> 0 | AV7: =IF(Y7="200",1,0) -> 0 | AW7: =sum(AR7:AV7) -> 2 | AY7: =AE7 -> 4 | AZ7: =AK7 -> 5 | BA7: =AQ7 -> 3 | BB7: =AW7 -> 2 | BC7: =sum(AY7:BB7)*5 -> 70
A8: =IFERROR(__xludf.DUMMYFUNCTION("""COMPUTED_VALUE"""),45920.47239439815) -> 45920.472 | B8: =IFERROR(__xludf.DUMMYFUNCTION("""COMPUTED_VALUE"""),"Aina Syahmina Givani") -> Aina Syahmina Givani | C8: =IFERROR(__xludf.DUMMYFUNCTION("""COMPUTED_VALUE"""),"D250006") -> D250006 | D8: =IFERROR(__xludf.DUMMYFUNCTION("""COMPUTED_VALUE"""),"MTs Putri") -> MTs Putri | E8: =IFERROR(__xludf.DUMMYFUNCTION("""COMPUTED_VALUE"""),"Ya") -> Ya | F8: =IFERROR(__xludf.DUMMYFUNCTION("""COMPUTED_VALUE"""),"B. Aku bersaksi bahwa tidak ada tuhan yang berhak di sembah kecuali Allah") -> B. Aku bersaksi bahwa tidak ada tuhan yang berhak di sembah kecuali Allah | G8: =IFERROR(__xludf.DUMMYFUNCTION("""COMPUTED_VALUE"""),6.0) -> 6 | H8: =IFERROR(__xludf.DUMMYFUNCTION("""COMPUTED_VALUE"""),"1 Syawwal") -> 1 Syawwal | I8: =IFERROR(__xludf.DUMMYFUNCTION("""COMPUTED_VALUE"""),"Al 'Alaq") -> Al 'Alaq | J8: =IFERROR(__xludf.DUMMYFUNCTION("""COMPUTED_VALUE"""),"Ali Bin Abi Thalib") -> Ali Bin Abi Thalib | K8: =IFERROR(__xludf.DUMMYFUNCTION("""COMPUTED_VALUE"""),"giat") -> giat | L8: =IFERROR(__xludf.DUMMYFUNCTION("""COMPUTED_VALUE"""),"dan") -> dan | M8: =IFERROR(__xludf.DUMMYFUNCTION("""COMPUTED_VALUE"""),"Hafsah mengatakan bahwa ia ingin belajar di pesantren.") -> Hafsah mengatakan bahwa ia ingin belajar di pesantren. | N8: =IFERROR(__xludf.DUMMYFUNCTION("""COMPUTED_VALUE"""),"Kalimat 1") -> Kalimat 1 | O8: =IFERROR(__xludf.DUMMYFUNCTION("""COMPUTED_VALUE"""),"cahaya") -> cahaya | P8: =IFERROR(__xludf.DUMMYFUNCTION("""COMPUTED_VALUE"""),"Parasitisme") -> Parasitisme | Q8: =IFERROR(__xludf.DUMMYFUNCTION("""COMPUTED_VALUE"""),"Angin") -> Angin | R8: =IFERROR(__xludf.DUMMYFUNCTION("""COMPUTED_VALUE"""),"belalang dan ular") -> belalang dan ular | S8: =IFERROR(__xludf.DUMMYFUNCTION("""COMPUTED_VALUE"""),"Menghasilkan klorofil") -> Menghasilkan klorofil | T8: =IFERROR(__xludf.DUMMYFUNCTION("""COMPUTED_VALUE"""),"Kelinci") -> Kelinci | U8: =IFERROR(__xludf.DUMMYFUNCTION("""COMPUTED_VALUE"""),-56.0) -> -56 | V8: =IFERROR(__xludf.DUMMYFUNCTION("""COMPUTED_VALUE"""),"3/4") -> 3/4 | W8: =IFERROR(__xludf.DUMMYFUNCTION("""COMPUTED_VALUE"""),"1.800 meter") -> 1.800 meter | X8: =IFERROR(__xludf.DUMMYFUNCTION("""COMPUTED_VALUE"""),"28 cm") -> 28 cm | Y8: =IFERROR(__xludf.DUMMYFUNCTION("""COMPUTED_VALUE"""),200.0) -> 200 | Z8: =IF(F8="B. Aku bersaksi bahwa tidak ada tuhan yang berhak di sembah kecuali Allah",1,0) -> 1 | AA8: =IF(G8=6,1,0) -> 1 | AB8: =IF(H8="1 Syawwal",1,0) -> 1 | AC8: =IF(I8="Al 'Alaq",1,0) -> 1 | AD8: =IF(J8="Ali Bin Abi Thalib",1,0) -> 1 | AE8: =sum(Z8:AD8) -> 5 | AF8: =IF(K8="giat",1,0) -> 1 | AG8: =IF(L8="dan",1,0) -> 1 | AH8: =IF(M8="Hafsah mengatakan bahwa ia ingin belajar di pesantren.",1,0) -> 1 | AI8: =IF(N8="Kalimat 1",1,0) -> 1 | AJ8: =IF(O8="cahaya",1,0) -> 1 | AK8: =sum(AF8:AJ8) -> 5 | AL8: =IF(P8="Parasitisme",1,0) -> 1 | AM8: =IF(Q8="Angin",1,0) -> 1 | AN8: =IF(R8="belalang dan ular",1,0) -> 1 | AO8: =IF(S8="Menghasilkan klorofil",1,0) -> 1 | AP8: =IF(T8="Kelinci",1,0) -> 1 | AQ8: =sum(AL8:AP8) -> 5 | AR8: =IF(U8=-64,1,0) -> 0 | AS8: =IF(V8="3/4",1,0) -> 1 | AT8: =IF(W8="1.800 meter",1,0) -> 1 | AU8: =IF(X8="22 cm",1,0) -> 0 | AV8: =IF(Y8="200",1,0) -> 0 | AW8: =sum(AR8:AV8) -> 2 | AY8: =AE8 -> 5 | AZ8: =AK8 -> 5 | BA8: =AQ8 -> 5 | BB8: =AW8 -> 2 | BC8: =sum(AY8:BB8)*5 -> 85
A9: =IFERROR(__xludf.DUMMYFUNCTION("""COMPUTED_VALUE"""),45920.49742675926) -> 45920.497 | B9: =IFERROR(__xludf.DUMMYFUNCTION("""COMPUTED_VALUE"""),"Aisyah") -> Aisyah | C9: =IFERROR(__xludf.DUMMYFUNCTION("""COMPUTED_VALUE"""),"D250005") -> D250005 | D9: =IFERROR(__xludf.DUMMYFUNCTION("""COMPUTED_VALUE"""),"MTs Putri") -> MTs Putri | E9: =IFERROR(__xludf.DUMMYFUNCTION("""COMPUTED_VALUE"""),"Ya") -> Ya | F9: =IFERROR(__xludf.DUMMYFUNCTION("""COMPUTED_VALUE"""),"B. Aku bersaksi bahwa tidak ada tuhan yang berhak di sembah kecuali Allah") -> B. Aku bersaksi bahwa tidak ada tuhan yang berhak di sembah kecuali Allah | G9: =IFERROR(__xludf.DUMMYFUNCTION("""COMPUTED_VALUE"""),6.0) -> 6 | H9: =IFERROR(__xludf.DUMMYFUNCTION("""COMPUTED_VALUE"""),"1 Syawwal") -> 1 Syawwal | I9: =IFERROR(__xludf.DUMMYFUNCTION("""COMPUTED_VALUE"""),"Al 'Alaq") -> Al 'Alaq | J9: =IFERROR(__xludf.DUMMYFUNCTION("""COMPUTED_VALUE"""),"Ali Bin Abi Thalib") -> Ali Bin Abi Thalib | K9: =IFERROR(__xludf.DUMMYFUNCTION("""COMPUTED_VALUE"""),"giat") -> giat | L9: =IFERROR(__xludf.DUMMYFUNCTION("""COMPUTED_VALUE"""),"dan") -> dan | M9: =IFERROR(__xludf.DUMMYFUNCTION("""COMPUTED_VALUE"""),"Hafsah mengatakan bahwa ia ingin belajar di pesantren.") -> Hafsah mengatakan bahwa ia ingin belajar di pesantren. | N9: =IFERROR(__xludf.DUMMYFUNCTION("""COMPUTED_VALUE"""),"Kalimat 1") -> Kalimat 1 | O9: =IFERROR(__xludf.DUMMYFUNCTION("""COMPUTED_VALUE"""),"kehidupan") -> kehidupan | P9: =IFERROR(__xludf.DUMMYFUNCTION("""COMPUTED_VALUE"""),"Parasitisme") -> Parasitisme | Q9: =IFERROR(__xludf.DUMMYFUNCTION("""COMPUTED_VALUE"""),"Angin") -> Angin | R9: =IFERROR(__xludf.DUMMYFUNCTION("""COMPUTED_VALUE"""),"belalang dan ular") -> belalang dan ular | S9: =IFERROR(__xludf.DUMMYFUNCTION("""COMPUTED_VALUE"""),"Menghasilkan klorofil") -> Menghasilkan klorofil | T9: =IFERROR(__xludf.DUMMYFUNCTION("""COMPUTED_VALUE"""),"Kelinci") -> Kelinci | U9: =IFERROR(__xludf.DUMMYFUNCTION("""COMPUTED_VALUE"""),-64.0) -> -64 | V9: =IFERROR(__xludf.DUMMYFUNCTION("""COMPUTED_VALUE"""),"3/4") -> 3/4 | W9: =IFERROR(__xludf.DUMMYFUNCTION("""COMPUTED_VALUE"""),"2.100 meter") -> 2.100 meter | X9: =IFERROR(__xludf.DUMMYFUNCTION("""COMPUTED_VALUE"""),"22 cm") -> 22 cm | Y9: =IFERROR(__xludf.DUMMYFUNCTION("""COMPUTED_VALUE"""),200.0) -> 200 | Z9: =IF(F9="B. Aku bersaksi bahwa tidak ada tuhan yang berhak di sembah kecuali Allah",1,0) -> 1 | AA9: =IF(G9=6,1,0) -> 1 | AB9: =IF(H9="1 Syawwal",1,0) -> 1 | AC9: =IF(I9="Al 'Alaq",1,0) -> 1 | AD9: =IF(J9="Ali Bin Abi Thalib",1,0) -> 1 | AE9: =sum(Z9:AD9) -> 5 | AF9: =IF(K9="giat",1,0) -> 1 | AG9: =IF(L9="dan",1,0) -> 1 | AH9: =IF(M9="Hafsah mengatakan bahwa ia ingin belajar di pesantren.",1,0) -> 1 | AI9: =IF(N9="Kalimat 1",1,0) -> 1 | AJ9: =IF(O9="cahaya",1,0) -> 0 | AK9: =sum(AF9:AJ9) -> 4 | AL9: =IF(P9="Parasitisme",1,0) -> 1 | AM9: =IF(Q9="Angin",1,0) -> 1 | AN9: =IF(R9="belalang dan ular",1,0) -> 1 | AO9: =IF(S9="Menghasilkan klorofil",1,0) -> 1 | AP9: =IF(T9="Kelinci",1,0) -> 1 | AQ9: =sum(AL9:AP9) -> 5 | AR9: =IF(U9=-64,1,0) -> 1 | AS9: =IF(V9="3/4",1,0) -> 1 | AT9: =IF(W9="1.800 meter",1,0) -> 0 | AU9: =IF(X9="22 cm",1,0) -> 1 | AV9: =IF(Y9="200",1,0) -> 0 | AW9: =sum(AR9:AV9) -> 3 | AY9: =AE9 -> 5 | AZ9: =AK9 -> 4 | BA9: =AQ9 -> 5 | BB9: =AW9 -> 3 | BC9: =sum(AY9:BB9)*5 -> 85
A10: =IFERROR(__xludf.DUMMYFUNCTION("""COMPUTED_VALUE"""),45920.66416510417) -> 45920.664 | B10: =IFERROR(__xludf.DUMMYFUNCTION("""COMPUTED_VALUE"""),"Sarah Afifa") -> Sarah Afifa | C10: =IFERROR(__xludf.DUMMYFUNCTION("""COMPUTED_VALUE"""),"D250015") -> D250015 | D10: =IFERROR(__xludf.DUMMYFUNCTION("""COMPUTED_VALUE"""),"MTs Putri") -> MTs Putri | E10: =IFERROR(__xludf.DUMMYFUNCTION("""COMPUTED_VALUE"""),"Ya") -> Ya | F10: =IFERROR(__xludf.DUMMYFUNCTION("""COMPUTED_VALUE"""),"B. Aku bersaksi bahwa tidak ada tuhan yang berhak di sembah kecuali Allah") -> B. Aku bersaksi bahwa tidak ada tuhan yang berhak di sembah kecuali Allah | G10: =IFERROR(__xludf.DUMMYFUNCTION("""COMPUTED_VALUE"""),6.0) -> 6 | H10: =IFERROR(__xludf.DUMMYFUNCTION("""COMPUTED_VALUE"""),"1 Syawwal") -> 1 Syawwal | I10: =IFERROR(__xludf.DUMMYFUNCTION("""COMPUTED_VALUE"""),"Al 'Alaq") -> Al 'Alaq | J10: =IFERROR(__xludf.DUMMYFUNCTION("""COMPUTED_VALUE"""),"Ali Bin Abi Thalib") -> Ali Bin Abi Thalib | K10: =IFERROR(__xludf.DUMMYFUNCTION("""COMPUTED_VALUE"""),"giat") -> giat | L10: =IFERROR(__xludf.DUMMYFUNCTION("""COMPUTED_VALUE"""),"dan") -> dan | M10: =IFERROR(__xludf.DUMMYFUNCTION("""COMPUTED_VALUE"""),"Hafsah mengatakan bahwa aku ingin belajar di pesantren.") -> Hafsah mengatakan bahwa aku ingin belajar di pesantren. | N10: =IFERROR(__xludf.DUMMYFUNCTION("""COMPUTED_VALUE"""),"Kalimat 1") -> Kalimat 1 | O10: =IFERROR(__xludf.DUMMYFUNCTION("""COMPUTED_VALUE"""),"cahaya") -> cahaya | P10: =IFERROR(__xludf.DUMMYFUNCTION("""COMPUTED_VALUE"""),"Mutualisme") -> Mutualisme | Q10: =IFERROR(__xludf.DUMMYFUNCTION("""COMPUTED_VALUE"""),"Angin") -> Angin | R10: =IFERROR(__xludf.DUMMYFUNCTION("""COMPUTED_VALUE"""),"belalang dan ular") -> belalang dan ular | S10: =IFERROR(__xludf.DUMMYFUNCTION("""COMPUTED_VALUE"""),"Menghasilkan klorofil") -> Menghasilkan klorofil | T10: =IFERROR(__xludf.DUMMYFUNCTION("""COMPUTED_VALUE"""),"Kelinci") -> Kelinci | U10: =IFERROR(__xludf.DUMMYFUNCTION("""COMPUTED_VALUE"""),56.0) -> 56 | V10: =IFERROR(__xludf.DUMMYFUNCTION("""COMPUTED_VALUE"""),"4/3") -> 4/3 | W10: =IFERROR(__xludf.DUMMYFUNCTION("""COMPUTED_VALUE"""),"1.800 meter") -> 1.800 meter | X10: =IFERROR(__xludf.DUMMYFUNCTION("""COMPUTED_VALUE"""),"22 cm") -> 22 cm | Y10: =IFERROR(__xludf.DUMMYFUNCTION("""COMPUTED_VALUE"""),200.0) -> 200 | Z10: =IF(F10="B. Aku bersaksi bahwa tidak ada tuhan yang berhak di sembah kecuali Allah",1,0) -> 1 | AA10: =IF(G10=6,1,0) -> 1 | AB10: =IF(H10="1 Syawwal",1,0) -> 1 | AC10: =IF(I10="Al 'Alaq",1,0) -> 1 | AD10: =IF(J10="Ali Bin Abi Thalib",1,0) -> 1 | AE10: =sum(Z10:AD10) -> 5 | AF10: =IF(K10="giat",1,0) -> 1 | AG10: =IF(L10="dan",1,0) -> 1 | AH10: =IF(M10="Hafsah mengatakan bahwa ia ingin belajar di pesantren.",1,0) -> 0 | AI10: =IF(N10="Kalimat 1",1,0) -> 1 | AJ10: =IF(O10="cahaya",1,0) -> 1 | AK10: =sum(AF10:AJ10) -> 4 | AL10: =IF(P10="Parasitisme",1,0) -> 0 | AM10: =IF(Q10="Angin",1,0) -> 1 | AN10: =IF(R10="belalang dan ular",1,0) -> 1 | AO10: =IF(S10="Menghasilkan klorofil",1,0) -> 1 | AP10: =IF(T10="Kelinci",1,0) -> 1 | AQ10: =sum(AL10:AP10) -> 4 | AR10: =IF(U10=-64,1,0) -> 0 | AS10: =IF(V10="3/4",1,0) -> 0 | AT10: =IF(W10="1.800 meter",1,0) -> 1 | AU10: =IF(X10="22 cm",1,0) -> 1 | AV10: =IF(Y10="200",1,0) -> 0 | AW10: =sum(AR10:AV10) -> 2 | AY10: =AE10 -> 5 | AZ10: =AK10 -> 4 | BA10: =AQ10 -> 4 | BB10: =AW10 -> 2 | BC10: =sum(AY10:BB10)*5 -> 75
A11: =IFERROR(__xludf.DUMMYFUNCTION("""COMPUTED_VALUE"""),45920.70911672454) -> 45920.709 | B11: =IFERROR(__xludf.DUMMYFUNCTION("""COMPUTED_VALUE"""),"Ambiaaddaruqutnijulpasa") -> Ambiaaddaruqutnijulpasa | C11: =IFERROR(__xludf.DUMMYFUNCTION("""COMPUTED_VALUE"""),"A250066") -> A250066 | D11: =IFERROR(__xludf.DUMMYFUNCTION("""COMPUTED_VALUE"""),"MTs Putra") -> MTs Putra | E11: =IFERROR(__xludf.DUMMYFUNCTION("""COMPUTED_VALUE"""),"Ya") -> Ya | F11: =IFERROR(__xludf.DUMMYFUNCTION("""COMPUTED_VALUE"""),"B. Aku bersaksi bahwa tidak ada tuhan yang berhak di sembah kecuali Allah") -> B. Aku bersaksi bahwa tidak ada tuhan yang berhak di sembah kecuali Allah | G11: =IFERROR(__xludf.DUMMYFUNCTION("""COMPUTED_VALUE"""),6.0) -> 6 | H11: =IFERROR(__xludf.DUMMYFUNCTION("""COMPUTED_VALUE"""),"1 Syawwal") -> 1 Syawwal | I11: =IFERROR(__xludf.DUMMYFUNCTION("""COMPUTED_VALUE"""),"Al 'Alaq") -> Al 'Alaq | J11: =IFERROR(__xludf.DUMMYFUNCTION("""COMPUTED_VALUE"""),"Utsman Bin Affan") -> Utsman Bin Affan | K11: =IFERROR(__xludf.DUMMYFUNCTION("""COMPUTED_VALUE"""),"giat") -> giat | L11: =IFERROR(__xludf.DUMMYFUNCTION("""COMPUTED_VALUE"""),"dan") -> dan | M11: =IFERROR(__xludf.DUMMYFUNCTION("""COMPUTED_VALUE"""),"Aku berkata Hafsah ingin belajar di pesantren.") -> Aku berkata Hafsah ingin belajar di pesantren. | N11: =IFERROR(__xludf.DUMMYFUNCTION("""COMPUTED_VALUE"""),"Kalimat 2") -> Kalimat 2 | O11: =IFERROR(__xludf.DUMMYFUNCTION("""COMPUTED_VALUE"""),"kehidupan") -> kehidupan | P11: =IFERROR(__xludf.DUMMYFUNCTION("""COMPUTED_VALUE"""),"Parasitisme") -> Parasitisme | Q11: =IFERROR(__xludf.DUMMYFUNCTION("""COMPUTED_VALUE"""),"Angin") -> Angin | R11: =IFERROR(__xludf.DUMMYFUNCTION("""COMPUTED_VALUE"""),"burung ketilang dan ulat") -> burung ketilang dan ulat | S11: =IFERROR(__xludf.DUMMYFUNCTION("""COMPUTED_VALUE"""),"Menghasilkan klorofil") -> Menghasilkan klorofil | T11: =IFERROR(__xludf.DUMMYFUNCTION("""COMPUTED_VALUE"""),"Kelinci") -> Kelinci | U11: =IFERROR(__xludf.DUMMYFUNCTION("""COMPUTED_VALUE"""),-56.0) -> -56 | V11: =IFERROR(__xludf.DUMMYFUNCTION("""COMPUTED_VALUE"""),"3/8") -> 3/8 | W11: =IFERROR(__xludf.DUMMYFUNCTION("""COMPUTED_VALUE"""),"1.800 meter") -> 1.800 meter | X11: =IFERROR(__xludf.DUMMYFUNCTION("""COMPUTED_VALUE"""),"28 cm") -> 28 cm | Y11: =IFERROR(__xludf.DUMMYFUNCTION("""COMPUTED_VALUE"""),1000.0) -> 1000 | Z11: =IF(F11="B. Aku bersaksi bahwa tidak ada tuhan yang berhak di sembah kecuali Allah",1,0) -> 1 | AA11: =IF(G11=6,1,0) -> 1 | AB11: =IF(H11="1 Syawwal",1,0) -> 1 | AC11: =IF(I11="Al 'Alaq",1,0) -> 1 | AD11: =IF(J11="Ali Bin Abi Thalib",1,0) -> 0 | AE11: =sum(Z11:AD11) -> 4 | AF11: =IF(K11="giat",1,0) -> 1 | AG11: =IF(L11="dan",1,0) -> 1 | AH11: =IF(M11="Hafsah mengatakan bahwa ia ingin belajar di pesantren.",1,0) -> 0 | AI11: =IF(N11="Kalimat 1",1,0) -> 0 | AJ11: =IF(O11="cahaya",1,0) -> 0 | AK11: =sum(AF11:AJ11) -> 2 | AL11: =IF(P11="Parasitisme",1,0) -> 1 | AM11: =IF(Q11="Angin",1,0) -> 1 | AN11: =IF(R11="belalang dan ular",1,0) -> 0 | AO11: =IF(S11="Menghasilkan klorofil",1,0) -> 1 | AP11: =IF(T11="Kelinci",1,0) -> 1 | AQ11: =sum(AL11:AP11) -> 4 | AR11: =IF(U11=-64,1,0) -> 0 | AS11: =IF(V11="3/4",1,0) -> 0 | AT11: =IF(W11="1.800 meter",1,0) -> 1 | AU11: =IF(X11="22 cm",1,0) -> 0 | AV11: =IF(Y11="200",1,0) -> 0 | AW11: =sum(AR11:AV11) -> 1 | AY11: =AE11 -> 4 | AZ11: =AK11 -> 2 | BA11: =AQ11 -> 4 | BB11: =AW11 -> 1 | BC11: =sum(AY11:BB11)*5 -> 55
